Workbook
Name revenueSize: #REF!

Sheet Cover Page
A1: a

Sheet PART 1 - Data Input & Sellabili
B3: Company Information | G3: Results
B4: Company | G4: Score | J4: =if((I26+I40)/((B25*5)+2)>1,1,(I26+I40)/((B25*5)+2)) -> 0.76623377
B5: Industry | G5: Grade | J5: =IFERROR(__xludf.DUMMYFUNCTION("IF($J$4>=0.9,""A"",IF(ISBETWEEN($J$4,0.75,0.8999999,TRUE,TRUE),""B"",IF(ISBETWEEN($J$4,0.6,0.74999999,TRUE,TRUE),""C"",IF(ISBETWEEN($J$4,0.5,0.599999999,TRUE,TRUE),""D"",""F""))))"),"B") -> B
B6: NAICS Code | C6: =VLOOKUP(C5,'NAICS Codes'!A3:N986,2,FALSE) -> #N/A | G6: Probability of Sale | J6: =IFERROR(__xludf.DUMMYFUNCTION("IF($J$4>=0.9,""Very High"",IF(ISBETWEEN($J$4,0.75,0.89999999,TRUE,TRUE),""High"",IF(ISBETWEEN($J$4,0.6,0.749999999,TRUE,TRUE),""Medium"",IF(ISBETWEEN($J$4,0.5,0.599999999,TRUE,TRUE),""Low"",""Very Low""))))"),"High") -> High
B8: STEP 1 - Risk Analysis
B9: # | C9: Question | H9: Answer | I9: Score | J9: Explanation
B10: 1 | C10: When is your fiscal year end?
B11: 2 | C11: Is your business incorporated? | H11: Yes | I11: =if(H11="yes",5,1) -> 5 | J11: =HYPERLINK("https://www.loom.com/share/9d8562379b304117ac81fe1cbc1a4f47?sid=0e799c1d-a2a7-4c47-9cc1-796944a33ad6",IMAGE("https://opnroad.io/wp-content/uploads/2023/09/Play-Button-White.png")) -> #REF!
B12: 3 | C12: Did your company report profit last year? | H12: Yes | I12: =if(H12="yes",5,1) -> 5 | J12: =HYPERLINK("https://www.loom.com/share/4b028328993c43b59eed98a73854fdce?sid=ba49cfca-afff-4615-8a96-934dd2daa728",IMAGE("https://opnroad.io/wp-content/uploads/2023/09/Play-Button-White.png")) -> #REF!
B13: 3 | C13: Did your company make profit in the last six months? | H13: Yes | I13: =if(H13="yes",5,1) -> 5 | J13: =HYPERLINK("https://www.loom.com/share/449ee8ffbfb14181a7ad4b3f5344a8e6?sid=6640bee3-f594-4b65-ade6-c95539440598",IMAGE("https://opnroad.io/wp-content/uploads/2023/09/Play-Button-White.png")) -> #REF!
B14: 4 | C14: What was your financial trend over the last five years? | H14: Modest YOY Steady Growth | I14: =If(H14="10%+ YOY Steady Growth",5,If(H14="Modest YOY Steady Growth",4,If(H14="Flat, steady and consistent",3,If(H14="Steadily declining",2,1)))) -> 4 | J14: =HYPERLINK("https://www.loom.com/share/60adf9ff1d1342b49cd78a6a0b8e03b2?sid=086dcf07-a1c1-45f3-9fa7-506497aa05cc",IMAGE("https://opnroad.io/wp-content/uploads/2023/09/Play-Button-White.png")) -> #REF!
B15: 5 | C15: How many years of clean accountant-generated financials do you have? | H15: 2 years | I15: =If(H15="5+ years",5,If(H15="3+ years",4,If(H15="2 years",3,If(H15="1 year",2,1)))) -> 3 | J15: =HYPERLINK("https://www.loom.com/share/90c3e112c27a4e0fb72ad586a1bcd67d?sid=a767a545-5bdf-4ced-8264-c15d6726623a",IMAGE("https://opnroad.io/wp-content/uploads/2023/09/Play-Button-White.png")) -> #REF!
B16: 6 | C16: Do you have a general manager that runs the business? | H16: No | I16: =if(H16="Yes",5,1) -> 1 | J16: =HYPERLINK("https://www.loom.com/share/7cb3c0769b1f4b3494a1e9f2536fa244?sid=43c696c8-d694-4c47-b140-6c9feb07f489",IMAGE("https://opnroad.io/wp-content/uploads/2023/09/Play-Button-White.png")) -> #REF!
B17: 7 | C17: Is your business project-based? | H17: Yes | I17: =if(H17="No",5,if(H17="Between",3,1)) -> 1 | J17: =HYPERLINK("https://www.loom.com/share/7d131b46a9ce40e3ae444c7e470e4414?sid=d5aeeb02-126a-44c0-9333-46457ba2a058",IMAGE("https://opnroad.io/wp-content/uploads/2023/09/Play-Button-White.png")) -> #REF!
B18: 8 | C18: What percent of sales does your largest customer represent? | H18: Between 5%-15% | I18: =If(H18="Under 1%",5,If(H18="Under 5%",4,If(H18="Between 5%-15%",3,If(H18="Over 15%",2,1)))) -> 3 | J18: =HYPERLINK("https://www.loom.com/share/9e49194d2a02483d8f919bf84ca15690?sid=09b67b44-59a7-4c58-b084-8f998f10d660",IMAGE("https://opnroad.io/wp-content/uploads/2023/09/Play-Button-White.png")) -> #REF!
B19: 9 | C19: How many hours a week do you work "IN" the business? | H19: 20 - 30 | I19: =If(H19="Under 10",5,If(H19="Under 20",4,If(H19="20 - 30",3,If(H19="30 - 50",2,1)))) -> 3 | J19: =HYPERLINK("https://www.loom.com/share/f6b319a604a744ccb4d75fd75c1503a3?sid=a4cb02a0-9654-41ed-b17d-61d019be75b0",IMAGE("https://opnroad.io/wp-content/uploads/2023/09/Play-Button-White.png")) -> #REF!
B20: 10 | C20: How much time is left on your lease, including renewal periods? | H20: Over 10 years | I20: =If(OR(H20="Over 10 years",H20="Building is Owned"),5,If(H20="Over 8 years",4,If(H20="5 - 8 years",3,If(H20="Under 5 years",2,1)))) -> 5 | J20: =HYPERLINK("https://www.loom.com/share/af95ee5b59484344b6511c5a8251c0c0?sid=32bc7160-5f06-4460-80a3-fe5c7fa91b76",IMAGE("https://opnroad.io/wp-content/uploads/2023/09/Play-Button-White.png")) -> #REF!
B21: 11 | C21: How long has your company been running? | H21: Over 15 years | I21: =If(H21="Over 25 years",5,If(H21="Over 15 years",4,If(H21="10 - 15 years",3,If(H21="Under 10 years",2,1)))) -> 4 | J21: =HYPERLINK("https://www.loom.com/share/e41406f41bdb43338af0b59f926956b1?sid=76a58883-61eb-4da3-b04b-df432a4f1bde",IMAGE("https://opnroad.io/wp-content/uploads/2023/09/Play-Button-White.png")) -> #REF!
B22: 12 | C22: What best describes your business operating system? | H22: Customized CRM | I22: =If(H22="Cloudbased ERP",5,If(H22="Customized CRM",4,If(H22="Basic CRM",3,If(H22="Excel Sheets",2,1)))) -> 4 | J22: =HYPERLINK("https://www.loom.com/share/64378f1a2ade43f1b393df7eada80c1f?sid=2015c2a0-2cda-4d15-a888-c9da6f165d44",IMAGE("https://opnroad.io/wp-content/uploads/2023/09/Play-Button-White.png")) -> #REF!
B23: 13 | C23: How do your customers pay you? | H23: 30 - 90 day terms | I23: =If(H23="Contracted Recurring Monthly Payments",5,if(H23="Some Reccuring Revenue",4,If(H23="Cash and Carry",3.5,If(H23="Deposit and Payment on Completion",3,If(H23="30 - 90 day terms",2,1))))) -> 2 | J23: =HYPERLINK("https://www.loom.com/share/312b05de41e54e7eb53e5224ad6a47b5?sid=db00a6e0-eaa4-4f70-a642-1c4fdbb5cca1",IMAGE("https://opnroad.io/wp-content/uploads/2023/09/Play-Button-White.png")) -> #REF!
B24: 14 | C24: (For Advisor) Number of single points of failure (SPOF)? | H24: 2 | I24: =If(H24=0,0,If(H24=1,-2,If(H24=2,-3,If(H24=3,-4,-5)))) -> -3 | J24: =HYPERLINK("https://www.loom.com/share/f910dc1c3beb47f991ded6f4646ca7af?sid=33bb5ff0-4c02-4a28-bf1b-9b809fa7ae52",IMAGE("https://opnroad.io/wp-content/uploads/2023/09/Play-Button-White.png")) -> #REF!
B25: 15 | C25: What do you need to sell your business for? Please explain. | E25: Off | G25: =iferror((I38*3.5)/H25,"") | I25: =iferror(if(E25="on",if(G25>1,1+(1+G25),-4*(1/G25)),5),5) -> 5 | J25: =HYPERLINK("https://www.loom.com/share/08589c5b0c4441a09f49304ee85347b9?sid=c8839835-98cc-42a4-925c-91ec471d3a53",IMAGE("https://opnroad.io/wp-content/uploads/2023/09/Play-Button-White.png")) -> #REF!
H26: Total | I26: =SUM(I11:I25) -> 47
B28: STEP 2 - Earnings Analysis
B29: # | C29: Question | E29: Baseline Margins | G29: Baseline | H29: From Financials | I29: Margins | J29: Explanation
B30: 1 | C30: What was your top line revenue last year? | E30: 1 | H30: 8000000 | I30: =IF(ISBLANK(H30), E30,H30/H30) -> 1 | J30: =HYPERLINK("https://www.loom.com/share/2d540e64f0ca4e45aeea99ff98df452c?sid=92a07b30-3157-4592-bbcd-a15e0c04e377",IMAGE("https://opnroad.io/wp-content/uploads/2023/09/Play-Button-White.png")) -> #REF!
B31: 2 | C31: What was your pre-tax profit last year? | E31: 0.075 | G31: =E31*$G$30 -> 0 | H31: =450000+800000 -> 1250000 | I31: =IF(ISBLANK(H30), E31,H31/$H$30) -> 0.15625 | J31: =HYPERLINK("https://www.loom.com/share/482816e8e6914313a291923b7f6b61e8?sid=82171146-49cd-4364-bbe9-bdb8ec796c85",IMAGE("https://opnroad.io/wp-content/uploads/2023/09/Play-Button-White.png")) -> #REF!
B32: 3 | C32: What was your amortization/depreciation last year? | E32: 0.01 | G32: =E32*$G$30 -> 0 | H32: 50000 | I32: =IF(ISBLANK(H30), E32,H32/$H$30) -> 0.00625 | J32: =HYPERLINK("https://www.loom.com/share/1cac7ad373f441999c6552be968c9fc0?sid=00c2aa63-1bbb-4114-9f68-efcf4c502711",IMAGE("https://opnroad.io/wp-content/uploads/2023/09/Play-Button-White.png")) -> #REF!
B33: 4 | C33: What was your long-term interest expense last year? | E33: 0.01 | G33: =E33*$G$30 -> 0 | H33: 0 | I33: =IF(ISBLANK(H30), E33,H33/$H$30) -> 0 | J33: =HYPERLINK("https://www.loom.com/share/50bf97edcc174c21b4c5ce47f7827888?sid=61236c03-d516-4e12-83b6-94265d3873f4",IMAGE("https://opnroad.io/wp-content/uploads/2023/09/Play-Button-White.png")) -> #REF!
B34: 5 | C34: What was your discretionary spending last year? | E34: 0.02 | G34: =E34*$G$30 -> 0 | H34: 60000 | I34: =IF(ISBLANK(H30), E34,H34/$H$30) -> 0.0075 | J34: =HYPERLINK("https://www.loom.com/share/6d326a1ad2094c80b2cd56bb789a13b5?sid=49948cd2-db6d-4cd8-ac3e-4d62cafe3166",IMAGE("https://opnroad.io/wp-content/uploads/2023/09/Play-Button-White.png")) -> #REF!
B35: 6 | C35: Do you pay yourself a salary above or below market rate? | H35: -50000 | J35: =HYPERLINK("https://www.loom.com/share/0dbd23d0a65f453689b448aed1d728a8?sid=e9f3de10-887c-40c5-a1b8-187d5c73b481",IMAGE("https://opnroad.io/wp-content/uploads/2023/09/Play-Button-White.png")) -> #REF!
B36: 7 | C36: Does your company pay market rate rent to yourself or the holdco? | H36: 0 | J36: =HYPERLINK("https://www.loom.com/share/f74bdb0d15194d71b77f01690a33fd83?sid=167407e5-653e-4c2c-a82c-a9ec79360b3d",IMAGE("https://opnroad.io/wp-content/uploads/2023/09/Play-Button-White.png")) -> #REF!
H38: EBITDA | I38: =IF(ISBLANK(H30),G31+G32+G33+G34+H35+H36,H31+H32+H33+H34+H35+H36) -> 1310000
H39: EBITDA Margin | I39: =IF(ISBLANK(H30),I38/G30,I38/H30) -> 0.16375
H40: Size Score | I40: =If(I38<'Data Page'!B5,'Data Page'!C5,IF(I38<'Data Page'!B6,'Data Page'!C6,IF(I38<'Data Page'!B7,'Data Page'!C7,IF(I38<'Data Page'!B8,'Data Page'!C8,IF(I38<'Data Page'!B9,'Data Page'!C9,IF(I38<'Data Page'!B10,'Data Page'!C10,IF(I38<'Data Page'!B11,'Data Page'!C11,IF(I38<'Data Page'!B12,'Data Page'!C12,IF(I38<'Data Page'!B13,'Data Page'!C13,'Data Page'!C14))))))))) -> 12
B42: STEP 3 - EBITDA Multiples
B43: # | C43: Question | H43: From Financials | J43: Explanation
B44: 1 | C44: What multiples would you like to use? | G44: Use Custom Multiple | J44: =HYPERLINK("https://www.loom.com/share/faf843c110b3461eb9064fd6be5b16a3?sid=19ae2917-8304-4dfa-b99f-8b58f69ff5fa",IMAGE("https://opnroad.io/wp-content/uploads/2023/09/Play-Button-White.png")) -> #REF!
B45: 2 | C45: Would you like risk weighting on or off? | G45: Risk Weighting On
B46: 3 | C46: Is the company Canadian? | G46: No
...

Sheet PART 2 - Value Acceleration Cal
D2: =Z16 -> 3930000 | V2: =W16 -> 12825000
C4: Target Size Increase | E4: 0.25 | I4: Target Efficiency Increase | K4: 0.05 | O4: Target EBITDA Increase | Q4: 1
B6: Size | H6: Efficiency | N6: Multiple (Risk) | T6: Forecasted P&L | Y6: Current P&L
C8: EBITDA | I8: EBITDA | O8: EBITDA | U8: Forecasted P&L | Y8: Current P&L
C9: Revenue | D9: =Z9*(E4+1) -> 10000000 | E9: 1 | I9: Revenue | J9: =Z9 -> 8000000 | K9: 1 | O9: Revenue | P9: =Z9 -> 8000000 | Q9: 1 | U9: Revenue | V9: =D9 -> 10000000 | W9: 1 | Y9: Revenue | Z9: =IF(ISBLANK('PART 1 - Data Input & Sellabili'!H30),'PART 1 - Data Input & Sellabili'!G30,'PART 1 - Data Input & Sellabili'!H30) -> 8000000 | AA9: 1
C10: COGS & Operating Expenses | D10: =D9*E10 -> 8437500 | E10: =AA10 -> 0.84375 | I10: COGS & Operating Expenses | J10: =J9*K10 -> 6350000 | K10: =AA10-K4 -> 0.79375 | O10: COGS & Operating Expenses | P10: =P9*Q10 -> 6750000 | Q10: =AA10 -> 0.84375 | U10: COGS & Operating Expenses | V10: =V9*W10 -> 7937500 | W10: =K10 -> 0.79375 | Y10: COGS & Operating Expenses | Z10: =Z9-Z11 -> 6750000 | AA10: =Z10/Z9 -> 0.84375
C11: Profit | D11: =D9-D10 -> 1562500 | E11: =AA11 -> 0.15625 | I11: Profit | J11: =J9-J10 -> 1650000 | K11: =J11/J9 -> 0.20625 | O11: Profit | P11: =P9-P10 -> 1250000 | Q11: =P11/P9 -> 0.15625 | U11: Profit | V11: =V9-V10 -> 2062500 | W11: =V11/V9 -> 0.20625 | Y11: Profit | Z11: =IF(ISBLANK('PART 1 - Data Input & Sellabili'!H31),'PART 1 - Data Input & Sellabili'!G31,'PART 1 - Data Input & Sellabili'!H31) -> 1250000 | AA11: =Z11/Z9 -> 0.15625
C12: Adj. EBITDA | D12: =D9*E12 -> 1637500 | E12: =AA12 -> 0.16375 | I12: Adj. EBITDA | J12: =J9*K12 -> 1710000 | K12: =AA12+(K11-AA11) -> 0.21375 | O12: Adj. EBITDA | P12: =P9*Q12 -> 1310000 | Q12: =AA12 -> 0.16375 | U12: Adj. EBITDA | V12: =W12*V9 -> 2137500 | W12: =AA12+(K11-AA11) -> 0.21375 | Y12: Adj. EBITDA | Z12: ='PART 1 - Data Input & Sellabili'!I38 -> 1310000 | AA12: =Z12/Z9 -> 0.16375
C14: Adjusted Value | I14: Adjusted Value | O14: Adjusted Value | U14: Forecasted Value | Y14: Current Value
C15: Multiple | E15: =Z15 -> 3 | I15: Multiple | K15: =Z15 -> 3 | O15: Multiple | Q15: =Z15+(Z15*Q4) -> 6 | U15: Multiple | W15: =Q15 -> 6 | Y15: Multiple | Z15: ='PART 1 - Data Input & Sellabili'!J54 -> 3
C16: Adjusted Value | E16: =E15*D12 -> 4912500 | I16: Value | K16: =K15*J12 -> 5130000 | O16: Value | Q16: =Q15*P12 -> 7860000 | U16: Sale Price | W16: =W15*V12 -> 12825000 | Y16: Current Value | Z16: =Z15*Z12 -> 3930000
C18: Value Created | I18: Value Created | O18: Value Created | U18: Forecasted Growth
C19: Sale Price Growth % | D19: =(E16-$Z$16)/$Z$16 -> 0.25 | I19: Sale Price Growth % | J19: =(K16-$Z$16)/$Z$16 -> 0.30534351 | O19: Sale Price Growth % | P19: =(Q16-$Z$16)/$Z$16 -> 1 | U19: Sale Price Growth % | W19: =W16/Z16-1 -> 2.2633588
C20: Sale Price Increase | D20: =E16-$Z$16 -> 982500 | I20: Sale Price Increase | J20: =K16-$Z$16 -> 1200000 | O20: Sale Price Increase | P20: =Q16-$Z$16 -> 3930000 | U20: Sale Price Increase | W20: =W16-Z16 -> 8895000
A52: ='PART 1 - Data Input & Sellabili'!A55 -> © OpnRoad 2023

Sheet PART 3 - Wealth Gap Calculator
C3: Step 1 - Current Scenario | K3: Step 2 - Exit Goals | Q3: Step 4 - Business Sale Price Target
C5: Current Annual Income | K5: Goals | Q5: Required Business Sale Price to Fund Portfolio
C6: Dividends | F6: 250000 | K6: Desired Post Sale Annual Income | M6: 400000 | Q6: Ownership Percentage | T6: 1
C7: Wages | F7: 0 | K7: Desired Exit Timeline (Years) | M7: 5 | Q7: Historical Annual Growth Rate | T7: 0.03
C8: Personal Expenses Covered by the Business | F8: 50000 | Q8: Long-Term Business Debt | T8: 0
C9: Other Passive Income | F9: 100000 | Q9: Net Proceeds Required After Debt Considerations | T9: =(T8*T6)+M16 -> 2425000
C10: Total Current Annual Income | F10: =SUM(F6:F9) -> 400000 | K10: Step 3 - Wealth Gap Calculation | Q10: Estimated Professional Fees & Taxes as % | T10: 0.1
Q11: Target Business Revenue | T11: =(T13/E24)/F30 -> 5430025.4
K12: Investment Portfolio Size
C13: Current Liquid Assets | K13: Replacement Income Required | M13: =M6-F9 -> 300000 | Q13: Target Business Sale Price | T13: =T9+(T9*T10) -> 2667500
C14: Cash or Liquid Assets Available to Invest | F14: 1500000 | K14: Return on Portfolio | M14: 0.075
C15: Non-Mortgage Debt | F15: 75000 | K15: Required Size of Investment portfolio | M15: =M13/M14 -> 4000000
C16: Net Available Assets | F16: =F14-F15 -> 1425000 | K16: Gap to Fully Fund Portfolio | M16: =M15-(F15+F14) -> 2425000
J20: User Entered
C21: Current Years to Exit | K21: Step 5 - Exit Planning
C23: Growth Rate | D23: Profit Margin | E23: Multiple | F23: Years to Exit | K23: Growth Rate | L23: Profit Margin | M23: Multiple | N23: Years to Exit
C24: =T7 -> 0.03 | D24: ='PART 2 - Value Acceleration Cal'!AA11 -> 0.15625 | E24: ='PART 2 - Value Acceleration Cal'!Z15 -> 3 | F24: =-1*(ln(T11/D33)/ln(1/(C24+1))) -> -13.109385 | K24: 0.05 | L24: 0.1 | M24: 4 | N24: =-1*(ln(L28/L33)/ln(1/(IF(J20="Data from VAC Tool",K25+1,K24+1)))) -> -5.2127262
K25: =T7 -> 0.03 | L25: ='PART 2 - Value Acceleration Cal'!W11 -> 0.20625 | M25: ='PART 2 - Value Acceleration Cal'!W15 -> 6
C27: Current Situation | F27: Margin | K27: Goal Situation | N27: Margin
C28: Revenue | D28: ='PART 2 - Value Acceleration Cal'!Z9 -> 8000000 | F28: ='PART 2 - Value Acceleration Cal'!AA9 -> 1 | K28: Revenue | L28: =L30/N30 -> 6203488.4 | N28: 1
C29: Profit | D29: ='PART 2 - Value Acceleration Cal'!Z11 -> 1250000 | F29: =D29/D28 -> 0.15625 | K29: Profit | L29: =L28*N29 -> 620348.84 | N29: =IF(J20="Data from VAC Tool", L25,L24) -> 0.1
C30: EBITDA | D30: ='PART 2 - Value Acceleration Cal'!Z12 -> 1310000 | F30: =D30/D28 -> 0.16375 | K30: EBITDA | L30: =IF(J20="Data from VAC Tool",T13/M25,T13/M24) -> 666875 | N30: =F30+(N29-F29) -> 0.1075
C32: Year | D32: Revenue | E32: EBITDA | F32: Sale Price | K32: Year | L32: Revenue | M32: EBITDA | N32: Sale Price
C33: 0 | D33: ='PART 2 - Value Acceleration Cal'!Z9 -> 8000000 | E33: ='PART 2 - Value Acceleration Cal'!Z11 -> 1250000 | F33: =E33*E24 -> 3750000 | K33: 0 | L33: =D28 -> 8000000 | M33: =D29 -> 1250000 | N33: =M33*M24 -> 5000000
C34: 1 | D34: =D33+(D33*$C$24) -> 8240000 | E34: =D34*$F$30 -> 1349300 | F34: =E34*$E$24 -> 4047900 | K34: 1 | L34: =L33+(L33*IF($J$20="Data from VAC Tool",$K$25,$K$24)) -> 8400000 | M34: =L34*$N$30 -> 903000 | N34: =M34*IF($J$20="Data from VAC Tool",$M$25,$M$24) -> 3612000
C35: 2 | D35: =D34+(D34*$C$24) -> 8487200 | E35: =D35*$F$30 -> 1389779 | F35: =E35*$E$24 -> 4169337 | K35: 2 | L35: =L34+(L34*IF($J$20="Data from VAC Tool",$K$25,$K$24)) -> 8820000 | M35: =L35*$N$30 -> 948150 | N35: =M35*IF($J$20="Data from VAC Tool",$M$25,$M$24) -> 3792600
C36: 3 | D36: =D35+(D35*$C$24) -> 8741816 | E36: =D36*$F$30 -> 1431472.4 | F36: =E36*$E$24 -> 4294417.1 | K36: 3 | L36: =L35+(L35*IF($J$20="Data from VAC Tool",$K$25,$K$24)) -> 9261000 | M36: =L36*$N$30 -> 995557.5 | N36: =M36*IF($J$20="Data from VAC Tool",$M$25,$M$24) -> 3982230
C37: 4 | D37: =D36+(D36*$C$24) -> 9004070.5 | E37: =D37*$F$30 -> 1474416.5 | F37: =E37*$E$24 -> 4423249.6 | K37: 4 | L37: =L36+(L36*IF($J$20="Data from VAC Tool",$K$25,$K$24)) -> 9724050 | M37: =L37*$N$30 -> 1045335.4 | N37: =M37*IF($J$20="Data from VAC Tool",$M$25,$M$24) -> 4181341.5
C38: 5 | D38: =D37+(D37*$C$24) -> 9274192.6 | E38: =D38*$F$30 -> 1518649 | F38: =E38*$E$24 -> 4555947.1 | K38: 5 | L38: =L37+(L37*IF($J$20="Data from VAC Tool",$K$25,$K$24)) -> 10210252 | M38: =L38*$N$30 -> 1097602.1 | N38: =M38*IF($J$20="Data from VAC Tool",$M$25,$M$24) -> 4390408.6
C39: 6 | D39: =D38+(D38*$C$24) -> 9552418.4 | E39: =D39*$F$30 -> 1564208.5 | F39: =E39*$E$24 -> 4692625.5 | K39: 6 | L39: =L38+(L38*IF($J$20="Data from VAC Tool",$K$25,$K$24)) -> 10720765 | M39: =L39*$N$30 -> 1152482.3 | N39: =M39*IF($J$20="Data from VAC Tool",$M$25,$M$24) -> 4609929
C40: 7 | D40: =D39+(D39*$C$24) -> 9838990.9 | E40: =D40*$F$30 -> 1611134.8 | F40: =E40*$E$24 -> 4833404.3 | K40: 7 | L40: =L39+(L39*IF($J$20="Data from VAC Tool",$K$25,$K$24)) -> 11256803 | M40: =L40*$N$30 -> 1210106.4 | N40: =M40*IF($J$20="Data from VAC Tool",$M$25,$M$24) -> 4840425.5
C41: 8 | D41: =D40+(D40*$C$24) -> 10134161 | E41: =D41*$F$30 -> 1659468.8 | F41: =E41*$E$24 -> 4978406.4 | K41: 8 | L41: =L40+(L40*IF($J$20="Data from VAC Tool",$K$25,$K$24)) -> 11819644 | M41: =L41*$N$30 -> 1270611.7 | N41: =M41*IF($J$20="Data from VAC Tool",$M$25,$M$24) -> 5082446.7
C42: 9 | D42: =D41+(D41*$C$24) -> 10438185 | E42: =D42*$F$30 -> 1709252.9 | F42: =E42*$E$24 -> 5127758.6 | K42: 9 | L42: =L41+(L41*IF($J$20="Data from VAC Tool",$K$25,$K$24)) -> 12410626 | M42: =L42*$N$30 -> 1334142.3 | N42: =M42*IF($J$20="Data from VAC Tool",$M$25,$M$24) -> 5336569.1
C43: 10 | D43: =D42+(D42*$C$24) -> 10751331 | E43: =D43*$F$30 -> 1760530.5 | F43: =E43*$E$24 -> 5281591.4 | K43: 10 | L43: =L42+(L42*IF($J$20="Data from VAC Tool",$K$25,$K$24)) -> 13031157 | M43: =L43*$N$30 -> 1400849.4 | N43: =M43*IF($J$20="Data from VAC Tool",$M$25,$M$24) -> 5603397.5
C44: 11 | D44: =D43+(D43*$C$24) -> 11073871 | E44: =D44*$F$30 -> 1813346.4 | F44: =E44*$E$24 -> 5440039.1 | K44: 11 | L44: =L43+(L43*IF($J$20="Data from VAC Tool",$K$25,$K$24)) -> 13682715 | M44: =L44*$N$30 -> 1470891.8 | N44: =M44*IF($J$20="Data from VAC Tool",$M$25,$M$24) -> 5883567.4
C45: 12 | D45: =D44+(D44*$C$24) -> 11406087 | E45: =D45*$F$30 -> 1867746.8 | F45: =E45*$E$24 -> 5603240.3 | K45: 12 | L45: =L44+(L44*IF($J$20="Data from VAC Tool",$K$25,$K$24)) -> 14366851 | M45: =L45*$N$30 -> 1544436.4 | N45: =M45*IF($J$20="Data from VAC Tool",$M$25,$M$24) -> 6177745.8
... C58: 25 | D58: =D57+(D57*$C$24) -> 16750223 | E58: =D58*$F$30 -> 2742849.1 | F58: =E58*$E$24 -> 8228547.3 | K58: 25 | L58: =L57+(L57*IF($J$20="Data from VAC Tool",$K$25,$K$24)) -> 27090840 | M58: =L58*$N$30 -> 2912265.2 | N58: =M58*IF($J$20="Data from VAC Tool",$M$25,$M$24) -> 11649061
A61: ='PART 2 - Value Acceleration Cal'!A52 -> © OpnRoad 2023

Sheet Single Points of Failure
B3: Types of Single Points of Failure (SPOF) | F3: Explanation
B4: NAME | C4: SEVERITY | D4: DESCRIPTION | F4: Single points of failure (SPOF) in a company refer to components, processes, or dependencies that, if they fail, can disrupt the entire operation. Identifying and mitigating SPOFs is crucial for ensuring business continuity. Here are some common examples of SPOFs that a company can have:
B5: Key Personnel | C5: High | D5: If the company heavily relies on one or a few individuals with critical skills or knowledge, their absence due to illness, resignation, or any other reason can be a significant SPOF.
B6: Customer Concentration | C6: Very High | D6: If the company has a single customer which is greater than 15% of annual revenue, the loss of this customer could be catastrophic.
B7: Supply Chain | C7: High | D7: Reliance on a single supplier for critical materials or components can create a SPOF. If that supplier encounters problems, it can disrupt production and supply.
B8: Commodity Based | C8: High | D8: If the company is heavily reliant on a specific commodity, a spike or drop in the commodity price, could cause the company to go under.
B9: Equipment Reliance | C9: Medium | D9: If the company is reliant on a single piece of equipment or machinery to produce a product or service, and the equipment becomes inoperable, this will lead to downtime. | F9: Mitigate Single Points of Failure
B10: Geography | C10: Medium | D10: If a company operates from a single geographic location and that location becomes inaccessible due to a disaster or other factors, it can result in a major disruption. | F10: To mitigate SPOFs, companies often employ strategies such as redundancy, disaster recovery planning, diversifying suppliers, cross-training employees, and implementing robust cybersecurity measures. Identifying and addressing SPOFs is an ongoing process to ensure business continuity and resilience.
B11: Data Centers | C11: Medium | D11: If all of a company's data and services are hosted in a single data center, any issues like power outages, natural disasters, or network failures at that data center could result in a major disruption.
B12: IT Security | C12: High | D12: If a company lacks robust security measures, a breach or cyberattack can compromise sensitive data and disrupt operations.
B13: Network Connectivity | C13: Medium | D13: Dependency on a single internet service provider (ISP) or a single network connection can be a SPOF. If that connection fails, it can cut off the company from external resources, customers, and even its own remote offices.
B14: Software Dependencies | C14: High | D14: When a company relies on specific software applications, and there's no contingency plan or alternative software available, a software failure can be a SPOF. | F14: Industry Data Links
B15: Power Supply | C15: Medium | D15: If the company doesn't have backup power sources (like generators or uninterruptible power supplies) and relies solely on the local power grid, a power outage can disrupt operations. | F15: SOURCE | I15: LINK
B16: Third-Party Service Providers | C16: Medium | D16: If a company heavily relies on third-party vendors for essential services like cloud hosting, payment processing, or customer support, a failure or downtime on the part of these vendors can affect the company. | F16: Business Valuation Resources | I16: https://www.bvresources.com/
B17: Hardware Components | C17: Medium | D17: If a company relies on a single server, router, or other critical hardware component without redundancy, a failure in that component can lead to system downtime. | F17: Business Reference Guide | I17: https://www.businessrg.com/
B18: Regulatory Compliance | C18: High | D18: Not adhering to industry regulations and standards can expose a company to legal issues and potential shutdowns. | F18: Peer Comps | I18: https://gvalue.com/peer-comps/
B19: Financial Dependencies | C19: Medium | D19: If a company depends on a single source of funding, like a major investor or a specific client, the loss of that source can be a financial SPOF. | F19: Vertical IQ | I19: https://verticaliq.com/
B20: Industry Activity | C20: High | D20: Is the industry at the end of its lifecycle or rapidly shrinking | F20: ValueSource | I20: https://www.valusource.com/
F21: BizMiner | I21: https://bizminer.com/
A23: ='PART 3 - Wealth Gap Calculator'!A61 -> © OpnRoad 2023

Sheet Contact
A69: ='Single Points of Failure'!$A$23 -> © OpnRoad 2023

Sheet Instructions
C3: VIDEO 1 - WHY & HOW TO USE | I3: VIDEO 2 - DETERMINING SELLABILITY
C5: CLICK HERE TO PLAY VIDEO | I5: CLICK HERE TO PLAY VIDEO
C20: VIDEO 3 - CALCULATING POTENTIAL VALUE | I20: VIDEO 4 - WEALTH GAP CALCULATOR
C22: CLICK HERE TO PLAY VIDEO | I22: CLICK HERE TO PLAY VIDEO
C972: VIDEO 5 - REPORT PRINTOUT & V7 UPGRADES | I972: VIDEO 6 - V8 UPGRADES
C974: CLICK HERE TO PLAY VIDEO | I974: CLICK HERE TO PLAY VIDEO
A988: © OpnRoad 2023

Sheet Data Page
B3: Company Size Score | E3: Probability Analysis | K3: Growth Potential
B4: Size of EBITDA | C4: Score | E4: Deviation from Mean | F4: EBITDA Multiple | G4: MVIC Price | H4: Probability | I4: STDEV | L4: Total | M4: Growth | N4: Current Value
B5: 100000 | C5: 0 | E5: -2 STDEV | F5: =IF('PART 1 - Data Input & Sellabili'!G44="Use Common Multiples",'PART 1 - Data Input & Sellabili'!D50,'PART 1 - Data Input & Sellabili'!D51) -> 1.7 | G5: =$I$22*F5 -> 2227000 | H5: 0.1 | I5: -2 | K5: Current Value | L5: =SUM(M5:N5) -> 3930000 | M5: 0 | N5: ='PART 2 - Value Acceleration Cal'!Z16 -> 3930000
B6: 250000 | C6: 1 | F6: =F5+(($F$9-$F$5)/4) -> 1.95 | G6: =$I$22*F6 -> 2554500 | H6: 0.2 | I6: -1.75 | K6: Increase Size | L6: =SUM(M6:N6) -> 4912500 | M6: ='PART 2 - Value Acceleration Cal'!E16-'PART 2 - Value Acceleration Cal'!Z16 -> 982500 | N6: ='PART 2 - Value Acceleration Cal'!Z16 -> 3930000
B7: 500000 | C7: 3 | E7: -1.5 STDEV | F7: =F6+(($F$9-$F$5)/4) -> 2.2 | G7: =$I$22*F7 -> 2882000 | H7: 0.3 | I7: -1.5 | K7: Improve Efficiency | L7: =SUM(M7:N7) -> 5130000 | M7: ='PART 2 - Value Acceleration Cal'!K16-'PART 2 - Value Acceleration Cal'!Z16 -> 1200000 | N7: ='PART 2 - Value Acceleration Cal'!Z16 -> 3930000
B8: 750000 | C8: 5 | F8: =F7+(($F$9-$F$5)/4) -> 2.45 | G8: =$I$22*F8 -> 3209500 | H8: 0.4 | I8: -1.25 | K8: Reduce Risk | L8: =SUM(M8:N8) -> 7860000 | M8: ='PART 2 - Value Acceleration Cal'!Q16-'PART 2 - Value Acceleration Cal'!Z16 -> 3930000 | N8: ='PART 2 - Value Acceleration Cal'!Z16 -> 3930000
B9: 1000000 | C9: 10 | E9: -1.0 STDEV | F9: =IF('PART 1 - Data Input & Sellabili'!G44="Use Common Multiples",'PART 1 - Data Input & Sellabili'!E50,'PART 1 - Data Input & Sellabili'!E51) -> 2.7 | G9: =$I$22*F9 -> 3537000 | H9: 0.5 | I9: -1 | K9: Total | L9: =SUM(M9:N9) -> 12825000 | M9: ='PART 2 - Value Acceleration Cal'!W20 -> 8895000 | N9: ='PART 2 - Value Acceleration Cal'!Z16 -> 3930000
B10: 1500000 | C10: 12 | F10: =F9+(($F$13-$F$9)/4) -> 2.775 | G10: =$I$22*F10 -> 3635250 | H10: 0.6 | I10: -0.75
B11: 2000000 | C11: 20 | E11: -0.5 STDEV | F11: =F10+(($F$13-$F$9)/4) -> 2.85 | G11: =$I$22*F11 -> 3733500 | H11: 0.7 | I11: -0.5
B12: 2500000 | C12: 25 | F12: =F11+(($F$13-$F$9)/4) -> 2.925 | G12: =$I$22*F12 -> 3831750 | H12: 0.8 | I12: -0.25
B13: 3000000 | C13: 30 | E13: 0 STDEV | F13: ='PART 2 - Value Acceleration Cal'!Z15 -> 3 | G13: =$I$22*F13 -> 3930000 | H13: 0.9 | I13: 0
B14: 3000000 | C14: 30 | F14: =F13+(($F$17-$F$13)/4) -> 3.675 | G14: =$I$22*F14 -> 4814250 | H14: 0.8 | I14: 0.25
E15: 0.5 STDEV | F15: =F14+(($F$17-$F$13)/4) -> 4.35 | G15: =$I$22*F15 -> 5698500 | H15: 0.7 | I15: =0.5 -> 0.5
B16: Industry Chosen | F16: =F15+(($F$17-$F$13)/4) -> 5.025 | G16: =$I$22*F16 -> 6582750 | H16: 0.6 | I16: 0.75
B17: Industry | C17: ='PART 1 - Data Input & Sellabili'!C5 | E17: 1.0 STDEV | F17: =IF('PART 1 - Data Input & Sellabili'!G44="Use Common Multiples",'PART 1 - Data Input & Sellabili'!H50,'PART 1 - Data Input & Sellabili'!H51) -> 5.7 | G17: =$I$22*F17 -> 7467000 | H17: 0.5 | I17: =1 -> 1
B18: Naics Code | C18: ='PART 1 - Data Input & Sellabili'!C6 -> #N/A | F18: =F17+(($F$21-$F$17)/4) -> 6.45 | G18: =$I$22*F18 -> 8449500 | H18: 0.4 | I18: 1.25
B19: Number of Businesses | C19: =VLOOKUP($C$17,'Multiple Data'!$A$3:$N$1014,4,FALSE) -> #REF! | E19: 1.5 STDEV | F19: =F18+(($F$21-$F$17)/4) -> 7.2 | G19: =$I$22*F19 -> 9432000 | H19: 0.3 | I19: =1.5 -> 1.5
F20: =F19+(($F$21-$F$17)/4) -> 7.95 | G20: =$I$22*F20 -> 10414500 | H20: 0.2 | I20: 1.75
B21: Post-Sale Cash Flow | E21: 2.0 STDEV | F21: =IF('PART 1 - Data Input & Sellabili'!G44="Use Common Multiples",'PART 1 - Data Input & Sellabili'!I50,'PART 1 - Data Input & Sellabili'!I51) -> 8.7 | G21: =$I$22*F21 -> 11397000 | H21: 0.1 | I21: 2
B22: Percent Invested | C22: 0.8 | E22: 1 STANDARD DEV. ----> | F22: =IF('PART 1 - Data Input & Sellabili'!G44="Use Common Multiples",(stdev('PART 1 - Data Input & Sellabili'!D50,'PART 1 - Data Input & Sellabili'!I50)),(stdev('PART 1 - Data Input & Sellabili'!D51,'PART 1 - Data Input & Sellabili'!I51))) -> 4.9497475 | G22: Company EBITDA ---> | I22: ='PART 2 - Value Acceleration Cal'!Z12 -> 1310000
B23: Invested Amount | C23: =C22*'PART 2 - Value Acceleration Cal'!W16 -> 10260000
B24: Estimated Return | C24: 0.12
B25: Annual Cash Flow | C25: =C24*C23 -> 1231200
A27: =Contact!A69 -> © OpnRoad 2023

Sheet NAICS Codes
A1: Industry NAICS Codes
A2: 2022 NAICS Title | B2: Naics Code
A3: 111110 - Soybean Farming | B3: 111110 | C3: Soybean Farming
A4: 111120 - Oilseed (except Soybean) Farming | B4: 111120 | C4: Oilseed (except Soybean) Farming
A5: 111130 - Dry Pea and Bean Farming | B5: 111130 | C5: Dry Pea and Bean Farming
A6: 111140 - Wheat Farming | B6: 111140 | C6: Wheat Farming
A7: 111150 - Corn Farming | B7: 111150 | C7: Corn Farming
A8: 111160 - Rice Farming | B8: 111160 | C8: Rice Farming
A9: 111191 - Oilseed and Grain Combination Farming | B9: 111191 | C9: Oilseed and Grain Combination Farming
A10: 111199 - All Other Grain Farming | B10: 111199 | C10: All Other Grain Farming
A11: 111211 - Potato Farming | B11: 111211 | C11: Potato Farming
A12: 111219 - Other Vegetable (except Potato) and Melon Farming | B12: 111219 | C12: Other Vegetable (except Potato) and Melon Farming
A13: 111310 - Orange Groves | B13: 111310 | C13: Orange Groves
A14: 111320 - Citrus (except Orange) Groves | B14: 111320 | C14: Citrus (except Orange) Groves
... A986: 928120 - International Affairs | B986: 928120 | C986: International Affairs
A987: ='Data Page'!A27 -> © OpnRoad 2023

Sheet Owner Questions
A2: Suggested Pre-Questions for Valuation Call
A4: 1 | B4: Why is this important to you?
A5: 2 | B5: Is there anything particular you want to acheive from our call today?
